<?xml version="1.0" ?>
<robot name="mono_b" xmlns:xacro="https://www.ros.org/wiki/xacro" >

  <!-- include the xacro files-->  
  <xacro:include filename="$(find mono_bot)/urdf/materials.xacro" />
  <xacro:include filename="$(find mono_bot)/urdf/mono_b.gazebo" />
  <xacro:include filename="$(find mono_bot)/urdf/macro.xacro" />

  <!-- Chasis defined here -->
  <link name="link_chassis">
    <pose>0 0 0 0 0 0</pose>
    <inertial>
      <mass value="1"/>
      <origin rpy="0 0 0" xyz="0 0 0"/>
      <inertia ixx="0.0395416666667" ixy="0" ixz="0" iyy="0.206208333333" iyz="0" izz="0.106208333333"/>
    </inertial>

    <collision name="collision_chassis">
      <geometry>
			<cylinder length="0.03" radius="0.13"/>
      </geometry>
    </collision>

    <visual>
      <origin rpy="0 0 0" xyz="0 0 0"/>
      <geometry>
        	<cylinder length="0.03" radius="0.13"/>
      </geometry>
      <material name="blue"/>
    </visual>
    </link>
 	
 	
    <!-- caster front -->
 	<link name="chasis_to_caster_link">	
 	<inertial>
      <mass value="0.01"/>
      <origin rpy="0 0 0" xyz="0 0 -0.0325"/>
      <inertia ixx="0.1" ixy="0" ixz="0" iyy="0.1" iyz="0" izz="0.01"/>
    </inertial>
    <collision name="chasis_to_caster_collision">
      <origin rpy=" 0 0 0" xyz="0 0 -0.0325"/>
      <geometry>
        <cylinder length="0.055" radius="0.015"/>
      </geometry>
      <surface>
        <friction>
          <ode>
            <mu>0.01</mu>
            <mu2>0.01</mu2>
          </ode>
        </friction>
      </surface>      
    </collision>    
    <visual name="chasis_to_caster_visual">
      <origin rpy=" 0 0 0" xyz="0 0 -0.0325"/>
      <geometry>
        <cylinder length="0.055" radius="0.015"/>
      </geometry>
    </visual>
 	</link>
 	
 	<!--// The SPHERE of the caster wheel is defined here -->
    <link name="castor_wheel">
 		<inertial>
          <mass value="0.5"/>
          <origin rpy="0 0 0" xyz="0 0 0"/>
          <inertia ixx="0.000526666666667" ixy="0" ixz="0" iyy="0.000526666666667" iyz="0" izz="0.000526666666667"/>
        </inertial>
        
        <collision name="link_caster_collision">
        <origin rpy="0 0 0" xyz="0 0 0"/>
          <geometry>
            <sphere radius="0.015"/>
          </geometry>
          <surface>
        <friction>
          <ode>
            <mu>0.1</mu>
            <mu2>0.1</mu2>
          </ode>
        </friction>
      </surface> 
        </collision>
        
        <visual name="link_caster">
          <origin rpy="0 0 0" xyz="0 0 0"/>
          <geometry>
            <sphere radius="0.015"/>
          </geometry>
        </visual>
     </link>
 
   <!-- Camera -->
  <link name="camera_link">
    <collision>
      <origin xyz="0 0 0" rpy="0 0 0"/>
      <geometry>
      <box size="0.01 0.06 0.06"/>
      </geometry>
    </collision>

    <visual>
      <origin xyz="0 0 0" rpy="0 0 0"/>
      <geometry>      
        <!-- <mesh filename="package://mono_bot/meshes/camera_box.dae" scale="1 1 1"/> -->
        <mesh filename="package://mono_bot/meshes/$(arg aruco_id)" scale="3 3 3"/>
        <!-- <box size="0.01 0.16 0.15"/>       -->
      </geometry>   
    </visual>

    <inertial>
      <mass value="1e-5" />
      <origin xyz="0 0 0" rpy="0 0 0"/>
      <inertia ixx="1e-6" ixy="0" ixz="0" iyy="1e-6" iyz="0" izz="1e-6" />
    </inertial>
  </link>
 
 
  <joint name="camera_joint" type="fixed">
    <axis xyz="0 1 0" />
    <origin xyz="0.05 0 0.115" rpy="0 0 0"/>
    <parent link="link_chassis"/>
    <child link="camera_link"/>
  </joint>

  <link name="camera_link_2">
    <collision>
      <origin xyz="0 0 0" rpy="0 0 0"/>
      <geometry>
        <box size="0.01 0.06 0.06"/>
      </geometry>
    </collision>

    <visual>
      <origin xyz="0 0 0" rpy="0 0 0"/>
      <geometry>
        <mesh filename="package://mono_bot/meshes/$(arg aruco_id)" scale="3 3 3"/>
    	  <!-- <box size="0.01 0.08 0.16"/> -->
      </geometry>
    </visual>

    <inertial>
      <mass value="1e-5" />
      <origin xyz="0 0 0" rpy="0 0 0"/>
      <inertia ixx="1e-6" ixy="0" ixz="0" iyy="1e-6" iyz="0" izz="1e-6" />
    </inertial>
  </link>
 
 
  <joint name="camera_joint_2" type="fixed">
    <axis xyz="0 1 0" />
    <origin xyz="-0.05 0 0.115" rpy="0 0 3.14"/>
    <parent link="link_chassis"/>
    <child link="camera_link_2"/>
  </joint>

  <joint name="chasis_to_cylinder_joint" type="continuous">
   	<axis rpy="0 0 0" xyz="0 0 1" />
    <origin xyz="0.085 0 -0.015" rpy="0 0 0"/>
    <parent link="link_chassis"/>
    <child link="chasis_to_caster_link"/>
  </joint>

  <joint name="cylinder_to_caster_joint" type="continuous">
  	<axis rpy="0 0 0" xyz="0 1 0" />
    <origin xyz="0.01 0 -0.065" rpy="0 0 0"/>
    <!-- origin xyz="0 0 0" rpy="0 0 0"/-->
    <parent link="chasis_to_caster_link"/>
    <child link="castor_wheel"/>
  </joint>
 
 
 
  <!-- Create wheel right -->  

   <xacro:link_wheel name="link_right_wheel" />
   <xacro:joint_wheel name="joint_right_wheel"  child="link_right_wheel"  origin_xyz="-0.07 0.145 -0.045"  />


  <!-- Left Wheel link -->

  <xacro:link_wheel name="link_left_wheel" />
  <xacro:joint_wheel name="joint_left_wheel"   child="link_left_wheel"   origin_xyz="-0.07 -0.145 -0.045"  />  

</robot>
